Workbook

Sheet README
A1: Red Chilli Powder Plant: Floor Data Collection (3 areas)
A3: What this is | B3: One workbook the floor fills in during the shift for a red chilli powder line: Cleaning (destoner, stalk remover, aspirator), Grinding (hammer mill and 40 mesh sieve, measured as one) and Packing (2 pouch fillers, 200 g). The same five record sheets are used by every area. The tool reads them, compares them with the Plan and tells the floor what to do.
A4: Line pace | B4: Grinding sets the pace: 1,000 kg good powder per hour. Cleaning must deliver 1,031 kg cleaned chilli per hour (from about 1,090 kg raw at 95% yield; cleaner capacity 1,300 kg raw). Packing: 2 fillers at 40 pouches/min, target 4,704 good 200 g pouches per hour.
A5: Shift pattern | B5: General shift 9:00 AM to 5:00 PM: 15 min start up, lunch 1:00 to 1:30 PM (line stops), 20 min cleaning from 4:40. 415 run minutes.
A6: Units | B6: Metric: kg, g, °C, Pa (dust extraction suction), ASTA colour units.
A7: Five floor records | B7: 1_Output (hourly), 2_Stops (every stop), 3_Settings (every check), 4_Changes (every change), 5_Response (every problem). Shift_Summary is calculated.
A8: Colour legend | B8: Blue text = entered on the floor. Black text = formula. Green text = pulled from the Plan. Yellow fill = owner standard.
A9: Test data | B9: Each area has one test shift with a planted problem: Cleaning on Mon 28 Sep, Grinding Wed 30 Sep, Packing Fri 2 Oct 2026. Answer_Key holds the expected finding. Do not feed Answer_Key to the LLM.
A10: Food safety note | B10: Chilli powder is a ready to eat product. Foreign matter, colour (ASTA) and seal integrity are both quality and FSSAI compliance points, so the LLM should treat them as hold decisions, not only output losses.

Sheet Plan
A1: Plan: owner standards (floor does not edit)
A3: A. Line standards
A4: Parameter | B4: Value | C4: Unit
A5: Grinding target (good powder) | B5: 1000 | C5: kg/hr
A6: Grinding yield (moisture, dust) | B6: 0.97 | C6: %
A7: Cleaning yield (stalks, stones, dust removed) | B7: 0.95 | C7: %
A8: Cleaned chilli needed per hour | B8: =B5/B6 -> 1030.9278 | C8: kg/hr
A9: Raw chilli feed needed | B9: =B8/B7 -> 1085.1872 | C9: kg/hr
A10: Cleaner capacity (raw) | B10: 1300 | C10: kg/hr
A11: Pouch size | B11: 200 | C11: g
A12: Pouch fillers on line | B12: 2 | C12: machines
A13: Filler target speed | B13: 40 | C13: pouches/min per machine
A14: Packing yield | B14: 0.98 | C14: %
A15: Hammer set life | B15: 400 | C15: run hours
A17: B. Shift schedule (general shift)
A18: Hour | B18: Available min | C18: Note
A19: 9:00-10:00 | B19: 45 | C19: 15 min start up
A20: 10:00-11:00 | B20: 60
A21: 11:00-12:00 | B21: 60
A22: 12:00-1:00 | B22: 60
A23: 1:00-2:00 | B23: 30 | C23: Lunch 1:00 to 1:30
A24: 2:00-3:00 | B24: 60
A25: 3:00-4:00 | B25: 60
A26: 4:00-5:00 | B26: 40 | C26: Cleaning from 4:40
A27: Total run minutes | B27: =SUM(B19:B26) -> 415
A29: C. Output rate per area
A30: Stage | B30: Product | C30: Output unit | D30: Rate per full hour | E30: Key
A31: Cleaning | B31: Chilli powder | C31: kg cleaned chilli | D31: =B8 -> 1030.9278 | E31: =A31&"|"&B31 -> Cleaning|Chilli powder
A32: Grinding | B32: Chilli powder | C32: kg good powder | D32: =B5 -> 1000 | E32: =A32&"|"&B32 -> Grinding|Chilli powder
A33: Packing | B33: Chilli powder | C33: good 200 g pouches | D33: =B12*B13*60*B14 -> 4704 | E33: =A33&"|"&B33 -> Packing|Chilli powder
A34: Cleaning target is what grinding needs, not cleaner capacity. All values are assumptions for a medium Indian chilli powder plant; replace with plant data.
A36: D. Critical setting spec limits
A37: Stage | B37: Parameter | C37: Applies to | D37: Min | E37: Max | F37: Unit | G37: Key
A38: Cleaning | B38: Raw feed rate | C38: All | D38: 1050 | E38: 1300 | F38: kg/hr | G38: =A38&"|"&B38&"|"&C38 -> Cleaning|Raw feed rate|All
A39: Cleaning | B39: Foreign matter and stalks in raw sample | C39: All | D39: 0 | E39: 2 | F39: % | G39: =A39&"|"&B39&"|"&C39 -> Cleaning|Foreign matter and stalks in raw sample|All
A40: Cleaning | B40: Reject bin since last check | C40: All | D40: 0 | E40: 35 | F40: kg | G40: =A40&"|"&B40&"|"&C40 -> Cleaning|Reject bin since last check|All
A41: Cleaning | B41: Cleaned chilli moisture | C41: All | D41: 8 | E41: 11 | F41: % | G41: =A41&"|"&B41&"|"&C41 -> Cleaning|Cleaned chilli moisture|All
A42: Grinding | B42: Mill feed rate | C42: All | D42: 1000 | E42: 1060 | F42: kg/hr | G42: =A42&"|"&B42&"|"&C42 -> Grinding|Mill feed rate|All
A43: Grinding | B43: Mill motor load | C43: All | D43: 80 | E43: 95 | F43: A | G43: =A43&"|"&B43&"|"&C43 -> Grinding|Mill motor load|All
A44: Grinding | B44: Powder temp at mill outlet | C44: All | D44: 30 | E44: 42 | F44: °C | G44: =A44&"|"&B44&"|"&C44 -> Grinding|Powder temp at mill outlet|All
...

Sheet 1_Output
A1: Date | B1: Stage | C1: Hour | D1: Product | E1: Good Count | F1: Reject Count | G1: Available Min | H1: Target | I1: Variance | J1: % of Target | K1: Running Good | L1: Running Target | M1: Recorded By
A2: 46293 | B2: Cleaning | C2: 9:00-10:00 | D2: Chilli powder | E2: 771 | F2: 41 | G2: =INDEX(Plan!$B$19:$B$26,MATCH(C2,Plan!$A$19:$A$26,0)) -> 45 | H2: =G2/60*INDEX(Plan!$D$31:$D$33,MATCH(B2&"|"&D2,Plan!$E$31:$E$33,0)) -> 773.19588 | I2: =E2-H2 -> -2.1958763 | J2: =IF(H2=0,"",E2/H2) -> 0.99716 | K2: =SUMIFS($E$2:E2,$B$2:B2,B2,$A$2:A2,A2) -> 771 | L2: =SUMIFS($H$2:H2,$B$2:B2,B2,$A$2:A2,A2) -> 773.19588 | M2: RS
A3: 46293 | B3: Cleaning | C3: 10:00-11:00 | D3: Chilli powder | E3: 1013 | F3: 71 | G3: =INDEX(Plan!$B$19:$B$26,MATCH(C3,Plan!$A$19:$A$26,0)) -> 60 | H3: =G3/60*INDEX(Plan!$D$31:$D$33,MATCH(B3&"|"&D3,Plan!$E$31:$E$33,0)) -> 1030.9278 | I3: =E3-H3 -> -17.927835 | J3: =IF(H3=0,"",E3/H3) -> 0.98261 | K3: =SUMIFS($E$2:E3,$B$2:B3,B3,$A$2:A3,A3) -> 1784 | L3: =SUMIFS($H$2:H3,$B$2:B3,B3,$A$2:A3,A3) -> 1804.1237 | M3: RS
A4: 46293 | B4: Cleaning | C4: 11:00-12:00 | D4: Chilli powder | E4: 731 | F4: 105 | G4: =INDEX(Plan!$B$19:$B$26,MATCH(C4,Plan!$A$19:$A$26,0)) -> 60 | H4: =G4/60*INDEX(Plan!$D$31:$D$33,MATCH(B4&"|"&D4,Plan!$E$31:$E$33,0)) -> 1030.9278 | I4: =E4-H4 -> -299.92784 | J4: =IF(H4=0,"",E4/H4) -> 0.70907 | K4: =SUMIFS($E$2:E4,$B$2:B4,B4,$A$2:A4,A4) -> 2515 | L4: =SUMIFS($H$2:H4,$B$2:B4,B4,$A$2:A4,A4) -> 2835.0515 | M4: RS
A5: 46293 | B5: Cleaning | C5: 12:00-1:00 | D5: Chilli powder | E5: 696 | F5: 98 | G5: =INDEX(Plan!$B$19:$B$26,MATCH(C5,Plan!$A$19:$A$26,0)) -> 60 | H5: =G5/60*INDEX(Plan!$D$31:$D$33,MATCH(B5&"|"&D5,Plan!$E$31:$E$33,0)) -> 1030.9278 | I5: =E5-H5 -> -334.92784 | J5: =IF(H5=0,"",E5/H5) -> 0.67512 | K5: =SUMIFS($E$2:E5,$B$2:B5,B5,$A$2:A5,A5) -> 3211 | L5: =SUMIFS($H$2:H5,$B$2:B5,B5,$A$2:A5,A5) -> 3865.9794 | M5: RS
A6: 46293 | B6: Cleaning | C6: 1:00-2:00 | D6: Chilli powder | E6: 520 | F6: 27 | G6: =INDEX(Plan!$B$19:$B$26,MATCH(C6,Plan!$A$19:$A$26,0)) -> 30 | H6: =G6/60*INDEX(Plan!$D$31:$D$33,MATCH(B6&"|"&D6,Plan!$E$31:$E$33,0)) -> 515.46392 | I6: =E6-H6 -> 4.5360825 | J6: =IF(H6=0,"",E6/H6) -> 1.0088 | K6: =SUMIFS($E$2:E6,$B$2:B6,B6,$A$2:A6,A6) -> 3731 | L6: =SUMIFS($H$2:H6,$B$2:B6,B6,$A$2:A6,A6) -> 4381.4433 | M6: RS
A7: 46293 | B7: Cleaning | C7: 2:00-3:00 | D7: Chilli powder | E7: 1028 | F7: 56 | G7: =INDEX(Plan!$B$19:$B$26,MATCH(C7,Plan!$A$19:$A$26,0)) -> 60 | H7: =G7/60*INDEX(Plan!$D$31:$D$33,MATCH(B7&"|"&D7,Plan!$E$31:$E$33,0)) -> 1030.9278 | I7: =E7-H7 -> -2.9278351 | J7: =IF(H7=0,"",E7/H7) -> 0.99716 | K7: =SUMIFS($E$2:E7,$B$2:B7,B7,$A$2:A7,A7) -> 4759 | L7: =SUMIFS($H$2:H7,$B$2:B7,B7,$A$2:A7,A7) -> 5412.3711 | M7: RS
A8: 46293 | B8: Cleaning | C8: 3:00-4:00 | D8: Chilli powder | E8: 1038 | F8: 55 | G8: =INDEX(Plan!$B$19:$B$26,MATCH(C8,Plan!$A$19:$A$26,0)) -> 60 | H8: =G8/60*INDEX(Plan!$D$31:$D$33,MATCH(B8&"|"&D8,Plan!$E$31:$E$33,0)) -> 1030.9278 | I8: =E8-H8 -> 7.0721649 | J8: =IF(H8=0,"",E8/H8) -> 1.00686 | K8: =SUMIFS($E$2:E8,$B$2:B8,B8,$A$2:A8,A8) -> 5797 | L8: =SUMIFS($H$2:H8,$B$2:B8,B8,$A$2:A8,A8) -> 6443.299 | M8: RS
A9: 46293 | B9: Cleaning | C9: 4:00-5:00 | D9: Chilli powder | E9: 690 | F9: 36 | G9: =INDEX(Plan!$B$19:$B$26,MATCH(C9,Plan!$A$19:$A$26,0)) -> 40 | H9: =G9/60*INDEX(Plan!$D$31:$D$33,MATCH(B9&"|"&D9,Plan!$E$31:$E$33,0)) -> 687.28522 | I9: =E9-H9 -> 2.7147766 | J9: =IF(H9=0,"",E9/H9) -> 1.00395 | K9: =SUMIFS($E$2:E9,$B$2:B9,B9,$A$2:A9,A9) -> 6487 | L9: =SUMIFS($H$2:H9,$B$2:B9,B9,$A$2:A9,A9) -> 7130.5842 | M9: RS
A10: 46295 | B10: Grinding | C10: 9:00-10:00 | D10: Chilli powder | E10: 681 | F10: 3 | G10: =INDEX(Plan!$B$19:$B$26,MATCH(C10,Plan!$A$19:$A$26,0)) -> 45 | H10: =G10/60*INDEX(Plan!$D$31:$D$33,MATCH(B10&"|"&D10,Plan!$E$31:$E$33,0)) -> 750 | I10: =E10-H10 -> -69 | J10: =IF(H10=0,"",E10/H10) -> 0.908 | K10: =SUMIFS($E$2:E10,$B$2:B10,B10,$A$2:A10,A10) -> 681 | L10: =SUMIFS($H$2:H10,$B$2:B10,B10,$A$2:A10,A10) -> 750 | M10: MK
A11: 46295 | B11: Grinding | C11: 10:00-11:00 | D11: Chilli powder | E11: 953 | F11: 4 | G11: =INDEX(Plan!$B$19:$B$26,MATCH(C11,Plan!$A$19:$A$26,0)) -> 60 | H11: =G11/60*INDEX(Plan!$D$31:$D$33,MATCH(B11&"|"&D11,Plan!$E$31:$E$33,0)) -> 1000 | I11: =E11-H11 -> -47 | J11: =IF(H11=0,"",E11/H11) -> 0.953 | K11: =SUMIFS($E$2:E11,$B$2:B11,B11,$A$2:A11,A11) -> 1634 | L11: =SUMIFS($H$2:H11,$B$2:B11,B11,$A$2:A11,A11) -> 1750 | M11: MK
A12: 46295 | B12: Grinding | C12: 11:00-12:00 | D12: Chilli powder | E12: 983 | F12: 4 | G12: =INDEX(Plan!$B$19:$B$26,MATCH(C12,Plan!$A$19:$A$26,0)) -> 60 | H12: =G12/60*INDEX(Plan!$D$31:$D$33,MATCH(B12&"|"&D12,Plan!$E$31:$E$33,0)) -> 1000 | I12: =E12-H12 -> -17 | J12: =IF(H12=0,"",E12/H12) -> 0.983 | K12: =SUMIFS($E$2:E12,$B$2:B12,B12,$A$2:A12,A12) -> 2617 | L12: =SUMIFS($H$2:H12,$B$2:B12,B12,$A$2:A12,A12) -> 2750 | M12: MK
A13: 46295 | B13: Grinding | C13: 12:00-1:00 | D13: Chilli powder | E13: 0 | F13: 1020 | G13: =INDEX(Plan!$B$19:$B$26,MATCH(C13,Plan!$A$19:$A$26,0)) -> 60 | H13: =G13/60*INDEX(Plan!$D$31:$D$33,MATCH(B13&"|"&D13,Plan!$E$31:$E$33,0)) -> 1000 | I13: =E13-H13 -> -1000 | J13: =IF(H13=0,"",E13/H13) -> 0 | K13: =SUMIFS($E$2:E13,$B$2:B13,B13,$A$2:A13,A13) -> 2617 | L13: =SUMIFS($H$2:H13,$B$2:B13,B13,$A$2:A13,A13) -> 3750 | M13: MK
... A25: 46297 | B25: Packing | C25: 4:00-5:00 | D25: Chilli powder | E25: 3152 | F25: 28 | G25: =INDEX(Plan!$B$19:$B$26,MATCH(C25,Plan!$A$19:$A$26,0)) -> 40 | H25: =G25/60*INDEX(Plan!$D$31:$D$33,MATCH(B25&"|"&D25,Plan!$E$31:$E$33,0)) -> 3136 | I25: =E25-H25 -> 16 | J25: =IF(H25=0,"",E25/H25) -> 1.005102 | K25: =SUMIFS($E$2:E25,$B$2:B25,B25,$A$2:A25,A25) -> 27664 | L25: =SUMIFS($H$2:H25,$B$2:B25,B25,$A$2:A25,A25) -> 32536 | M25: PD
A27: Units: Cleaning = kg cleaned chilli (reject = kg stalks, stones, dust removed), Grinding = kg good powder (reject = kg held by QA or swept), Packing = 200 g pouches (reject = leakers, weight rejects).

Sheet 2_Stops
A1: Date | B1: Stage | C1: Start | D1: End | E1: Minutes | F1: Stop Type | G1: 4M Reason | H1: What Happened | I1: Recorded By
A2: 46293 | B2: Cleaning | C2: 0.42013889 | D2: 0.42222222 | E2: =IF(OR(C2="",D2=""),"",ROUND((D2-C2)*1440,0)) -> 3 | F2: Minor stop | G2: Machine | H2: Destoner feed chute blocked, cleared | I2: RS
A3: 46293 | B3: Cleaning | C3: 0.46527778 | D3: 0.47222222 | E3: =IF(OR(C3="",D3=""),"",ROUND((D3-C3)*1440,0)) -> 10 | F3: Line blocked (buffer full) | G3: Material | H3: Reject bin overflowed, stopped feed and emptied bin | I3: RS
A4: 46293 | B4: Cleaning | C4: 0.51041667 | D4: 0.51736111 | E4: =IF(OR(C4="",D4=""),"",ROUND((D4-C4)*1440,0)) -> 10 | F4: Line blocked (buffer full) | G4: Material | H4: Reject bin overflowed again, emptied | I4: RS
A5: 46293 | B5: Cleaning | C5: 0.62847222 | D5: 0.63055556 | E5: =IF(OR(C5="",D5=""),"",ROUND((D5-C5)*1440,0)) -> 3 | F5: Minor stop | G5: Machine | H5: Aspirator screen brushed | I5: RS
A6: 46295 | B6: Grinding | C6: 0.40833333 | D6: 0.41041667 | E6: =IF(OR(C6="",D6=""),"",ROUND((D6-C6)*1440,0)) -> 3 | F6: Minor stop | G6: Machine | H6: Sieve blinded, brushed screen | I6: MK
A7: 46295 | B7: Grinding | C7: 0.48819444 | D7: 0.49097222 | E7: =IF(OR(C7="",D7=""),"",ROUND((D7-C7)*1440,0)) -> 4 | F7: Minor stop | G7: Machine | H7: Sieve blinded, brushed screen, powder feels warm | I7: MK
A8: 46295 | B8: Grinding | C8: 0.59375 | D8: 0.625 | E8: =IF(OR(C8="",D8=""),"",ROUND((D8-C8)*1440,0)) -> 45 | F8: Breakdown | G8: Machine | H8: Maintenance replacing hammer set (412 plus hours) | I8: MK
A9: 46297 | B9: Packing | C9: 0.48333333 | D9: 0.48541667 | E9: =IF(OR(C9="",D9=""),"",ROUND((D9-C9)*1440,0)) -> 3 | F9: Minor stop | G9: Machine | H9: Filler 1 jaws jammed, spice dust on film, cleaned | I9: PD
A10: 46297 | B10: Packing | C10: 0.49375 | D10: 0.49583333 | E10: =IF(OR(C10="",D10=""),"",ROUND((D10-C10)*1440,0)) -> 3 | F10: Minor stop | G10: Machine | H10: Filler 2 jaws jammed, spice dust on film, cleaned | I10: PD
A11: 46297 | B11: Packing | C11: 0.50416667 | D11: 0.50625 | E11: =IF(OR(C11="",D11=""),"",ROUND((D11-C11)*1440,0)) -> 3 | F11: Minor stop | G11: Machine | H11: Filler 1 jaws jammed, spice dust on film, cleaned | I11: PD
A12: 46297 | B12: Packing | C12: 0.51458333 | D12: 0.51666667 | E12: =IF(OR(C12="",D12=""),"",ROUND((D12-C12)*1440,0)) -> 3 | F12: Minor stop | G12: Machine | H12: Filler 2 jaws jammed, spice dust on film, cleaned | I12: PD
A13: 46297 | B13: Packing | C13: 0.52361111 | D13: 0.52569444 | E13: =IF(OR(C13="",D13=""),"",ROUND((D13-C13)*1440,0)) -> 3 | F13: Minor stop | G13: Machine | H13: Filler 1 jaws jammed, spice dust on film, cleaned | I13: PD
... A20: 46297 | B20: Packing | C20: 0.61111111 | D20: 0.625 | E20: =IF(OR(C20="",D20=""),"",ROUND((D20-C20)*1440,0)) -> 20 | F20: Cleaning | G20: Machine | H20: Stopped both fillers to clean jaws after maintenance restored dust extraction | I20: PD

Sheet 3_Settings
A1: Date | B1: Stage | C1: Check Time | D1: Parameter | E1: Applies To | F1: Reading | G1: Unit | H1: Min | I1: Max | J1: In Spec | K1: Recorded By
A2: 46293 | B2: Cleaning | C2: 0.39583333 | D2: Raw feed rate | E2: Chilli powder | F2: 1090 | G2: =IFERROR(INDEX(Plan!$F$38:$F$51,MATCH(B2&"|"&D2&"|"&E2,Plan!$G$38:$G$51,0)),INDEX(Plan!$F$38:$F$51,MATCH(B2&"|"&D2&"|All",Plan!$G$38:$G$51,0))) -> kg/hr | H2: =IFERROR(INDEX(Plan!$D$38:$D$51,MATCH(B2&"|"&D2&"|"&E2,Plan!$G$38:$G$51,0)),INDEX(Plan!$D$38:$D$51,MATCH(B2&"|"&D2&"|All",Plan!$G$38:$G$51,0))) -> 1050 | I2: =IFERROR(INDEX(Plan!$E$38:$E$51,MATCH(B2&"|"&D2&"|"&E2,Plan!$G$38:$G$51,0)),INDEX(Plan!$E$38:$E$51,MATCH(B2&"|"&D2&"|All",Plan!$G$38:$G$51,0))) -> 1300 | J2: =IF(F2="","MISSING",IF(AND(F2>=H2,F2<=I2),"OK","OUT")) -> OK | K2: RS
A3: 46293 | B3: Cleaning | C3: 0.39583333 | D3: Foreign matter and stalks in raw sample | E3: Chilli powder | F3: 1.4 | G3: =IFERROR(INDEX(Plan!$F$38:$F$51,MATCH(B3&"|"&D3&"|"&E3,Plan!$G$38:$G$51,0)),INDEX(Plan!$F$38:$F$51,MATCH(B3&"|"&D3&"|All",Plan!$G$38:$G$51,0))) -> % | H3: =IFERROR(INDEX(Plan!$D$38:$D$51,MATCH(B3&"|"&D3&"|"&E3,Plan!$G$38:$G$51,0)),INDEX(Plan!$D$38:$D$51,MATCH(B3&"|"&D3&"|All",Plan!$G$38:$G$51,0))) -> 0 | I3: =IFERROR(INDEX(Plan!$E$38:$E$51,MATCH(B3&"|"&D3&"|"&E3,Plan!$G$38:$G$51,0)),INDEX(Plan!$E$38:$E$51,MATCH(B3&"|"&D3&"|All",Plan!$G$38:$G$51,0))) -> 2 | J3: =IF(F3="","MISSING",IF(AND(F3>=H3,F3<=I3),"OK","OUT")) -> OK | K3: RS
A4: 46293 | B4: Cleaning | C4: 0.39583333 | D4: Reject bin since last check | E4: Chilli powder | F4: 14 | G4: =IFERROR(INDEX(Plan!$F$38:$F$51,MATCH(B4&"|"&D4&"|"&E4,Plan!$G$38:$G$51,0)),INDEX(Plan!$F$38:$F$51,MATCH(B4&"|"&D4&"|All",Plan!$G$38:$G$51,0))) -> kg | H4: =IFERROR(INDEX(Plan!$D$38:$D$51,MATCH(B4&"|"&D4&"|"&E4,Plan!$G$38:$G$51,0)),INDEX(Plan!$D$38:$D$51,MATCH(B4&"|"&D4&"|All",Plan!$G$38:$G$51,0))) -> 0 | I4: =IFERROR(INDEX(Plan!$E$38:$E$51,MATCH(B4&"|"&D4&"|"&E4,Plan!$G$38:$G$51,0)),INDEX(Plan!$E$38:$E$51,MATCH(B4&"|"&D4&"|All",Plan!$G$38:$G$51,0))) -> 35 | J4: =IF(F4="","MISSING",IF(AND(F4>=H4,F4<=I4),"OK","OUT")) -> OK | K4: RS
A5: 46293 | B5: Cleaning | C5: 0.39583333 | D5: Cleaned chilli moisture | E5: Chilli powder | F5: 9.7 | G5: =IFERROR(INDEX(Plan!$F$38:$F$51,MATCH(B5&"|"&D5&"|"&E5,Plan!$G$38:$G$51,0)),INDEX(Plan!$F$38:$F$51,MATCH(B5&"|"&D5&"|All",Plan!$G$38:$G$51,0))) -> % | H5: =IFERROR(INDEX(Plan!$D$38:$D$51,MATCH(B5&"|"&D5&"|"&E5,Plan!$G$38:$G$51,0)),INDEX(Plan!$D$38:$D$51,MATCH(B5&"|"&D5&"|All",Plan!$G$38:$G$51,0))) -> 8 | I5: =IFERROR(INDEX(Plan!$E$38:$E$51,MATCH(B5&"|"&D5&"|"&E5,Plan!$G$38:$G$51,0)),INDEX(Plan!$E$38:$E$51,MATCH(B5&"|"&D5&"|All",Plan!$G$38:$G$51,0))) -> 11 | J5: =IF(F5="","MISSING",IF(AND(F5>=H5,F5<=I5),"OK","OUT")) -> OK | K5: RS
A6: 46293 | B6: Cleaning | C6: 0.41666667 | D6: Raw feed rate | E6: Chilli powder | F6: 1090 | G6: =IFERROR(INDEX(Plan!$F$38:$F$51,MATCH(B6&"|"&D6&"|"&E6,Plan!$G$38:$G$51,0)),INDEX(Plan!$F$38:$F$51,MATCH(B6&"|"&D6&"|All",Plan!$G$38:$G$51,0))) -> kg/hr | H6: =IFERROR(INDEX(Plan!$D$38:$D$51,MATCH(B6&"|"&D6&"|"&E6,Plan!$G$38:$G$51,0)),INDEX(Plan!$D$38:$D$51,MATCH(B6&"|"&D6&"|All",Plan!$G$38:$G$51,0))) -> 1050 | I6: =IFERROR(INDEX(Plan!$E$38:$E$51,MATCH(B6&"|"&D6&"|"&E6,Plan!$G$38:$G$51,0)),INDEX(Plan!$E$38:$E$51,MATCH(B6&"|"&D6&"|All",Plan!$G$38:$G$51,0))) -> 1300 | J6: =IF(F6="","MISSING",IF(AND(F6>=H6,F6<=I6),"OK","OUT")) -> OK | K6: RS
A7: 46293 | B7: Cleaning | C7: 0.41666667 | D7: Foreign matter and stalks in raw sample | E7: Chilli powder | F7: 1.7 | G7: =IFERROR(INDEX(Plan!$F$38:$F$51,MATCH(B7&"|"&D7&"|"&E7,Plan!$G$38:$G$51,0)),INDEX(Plan!$F$38:$F$51,MATCH(B7&"|"&D7&"|All",Plan!$G$38:$G$51,0))) -> % | H7: =IFERROR(INDEX(Plan!$D$38:$D$51,MATCH(B7&"|"&D7&"|"&E7,Plan!$G$38:$G$51,0)),INDEX(Plan!$D$38:$D$51,MATCH(B7&"|"&D7&"|All",Plan!$G$38:$G$51,0))) -> 0 | I7: =IFERROR(INDEX(Plan!$E$38:$E$51,MATCH(B7&"|"&D7&"|"&E7,Plan!$G$38:$G$51,0)),INDEX(Plan!$E$38:$E$51,MATCH(B7&"|"&D7&"|All",Plan!$G$38:$G$51,0))) -> 2 | J7: =IF(F7="","MISSING",IF(AND(F7>=H7,F7<=I7),"OK","OUT")) -> OK | K7: RS
A8: 46293 | B8: Cleaning | C8: 0.41666667 | D8: Reject bin since last check | E8: Chilli powder | F8: 27 | G8: =IFERROR(INDEX(Plan!$F$38:$F$51,MATCH(B8&"|"&D8&"|"&E8,Plan!$G$38:$G$51,0)),INDEX(Plan!$F$38:$F$51,MATCH(B8&"|"&D8&"|All",Plan!$G$38:$G$51,0))) -> kg | H8: =IFERROR(INDEX(Plan!$D$38:$D$51,MATCH(B8&"|"&D8&"|"&E8,Plan!$G$38:$G$51,0)),INDEX(Plan!$D$38:$D$51,MATCH(B8&"|"&D8&"|All",Plan!$G$38:$G$51,0))) -> 0 | I8: =IFERROR(INDEX(Plan!$E$38:$E$51,MATCH(B8&"|"&D8&"|"&E8,Plan!$G$38:$G$51,0)),INDEX(Plan!$E$38:$E$51,MATCH(B8&"|"&D8&"|All",Plan!$G$38:$G$51,0))) -> 35 | J8: =IF(F8="","MISSING",IF(AND(F8>=H8,F8<=I8),"OK","OUT")) -> OK | K8: RS
A9: 46293 | B9: Cleaning | C9: 0.41666667 | D9: Cleaned chilli moisture | E9: Chilli powder | F9: 10.1 | G9: =IFERROR(INDEX(Plan!$F$38:$F$51,MATCH(B9&"|"&D9&"|"&E9,Plan!$G$38:$G$51,0)),INDEX(Plan!$F$38:$F$51,MATCH(B9&"|"&D9&"|All",Plan!$G$38:$G$51,0))) -> % | H9: =IFERROR(INDEX(Plan!$D$38:$D$51,MATCH(B9&"|"&D9&"|"&E9,Plan!$G$38:$G$51,0)),INDEX(Plan!$D$38:$D$51,MATCH(B9&"|"&D9&"|All",Plan!$G$38:$G$51,0))) -> 8 | I9: =IFERROR(INDEX(Plan!$E$38:$E$51,MATCH(B9&"|"&D9&"|"&E9,Plan!$G$38:$G$51,0)),INDEX(Plan!$E$38:$E$51,MATCH(B9&"|"&D9&"|All",Plan!$G$38:$G$51,0))) -> 11 | J9: =IF(F9="","MISSING",IF(AND(F9>=H9,F9<=I9),"OK","OUT")) -> OK | K9: RS
A10: 46293 | B10: Cleaning | C10: 0.4375 | D10: Raw feed rate | E10: Chilli powder | F10: 1090 | G10: =IFERROR(INDEX(Plan!$F$38:$F$51,MATCH(B10&"|"&D10&"|"&E10,Plan!$G$38:$G$51,0)),INDEX(Plan!$F$38:$F$51,MATCH(B10&"|"&D10&"|All",Plan!$G$38:$G$51,0))) -> kg/hr | H10: =IFERROR(INDEX(Plan!$D$38:$D$51,MATCH(B10&"|"&D10&"|"&E10,Plan!$G$38:$G$51,0)),INDEX(Plan!$D$38:$D$51,MATCH(B10&"|"&D10&"|All",Plan!$G$38:$G$51,0))) -> 1050 | I10: =IFERROR(INDEX(Plan!$E$38:$E$51,MATCH(B10&"|"&D10&"|"&E10,Plan!$G$38:$G$51,0)),INDEX(Plan!$E$38:$E$51,MATCH(B10&"|"&D10&"|All",Plan!$G$38:$G$51,0))) -> 1300 | J10: =IF(F10="","MISSING",IF(AND(F10>=H10,F10<=I10),"OK","OUT")) -> OK | K10: RS
A11: 46293 | B11: Cleaning | C11: 0.4375 | D11: Foreign matter and stalks in raw sample | E11: Chilli powder | F11: 1.7 | G11: =IFERROR(INDEX(Plan!$F$38:$F$51,MATCH(B11&"|"&D11&"|"&E11,Plan!$G$38:$G$51,0)),INDEX(Plan!$F$38:$F$51,MATCH(B11&"|"&D11&"|All",Plan!$G$38:$G$51,0))) -> % | H11: =IFERROR(INDEX(Plan!$D$38:$D$51,MATCH(B11&"|"&D11&"|"&E11,Plan!$G$38:$G$51,0)),INDEX(Plan!$D$38:$D$51,MATCH(B11&"|"&D11&"|All",Plan!$G$38:$G$51,0))) -> 0 | I11: =IFERROR(INDEX(Plan!$E$38:$E$51,MATCH(B11&"|"&D11&"|"&E11,Plan!$G$38:$G$51,0)),INDEX(Plan!$E$38:$E$51,MATCH(B11&"|"&D11&"|All",Plan!$G$38:$G$51,0))) -> 2 | J11: =IF(F11="","MISSING",IF(AND(F11>=H11,F11<=I11),"OK","OUT")) -> OK | K11: RS
A12: 46293 | B12: Cleaning | C12: 0.4375 | D12: Reject bin since last check | E12: Chilli powder | F12: 27 | G12: =IFERROR(INDEX(Plan!$F$38:$F$51,MATCH(B12&"|"&D12&"|"&E12,Plan!$G$38:$G$51,0)),INDEX(Plan!$F$38:$F$51,MATCH(B12&"|"&D12&"|All",Plan!$G$38:$G$51,0))) -> kg | H12: =IFERROR(INDEX(Plan!$D$38:$D$51,MATCH(B12&"|"&D12&"|"&E12,Plan!$G$38:$G$51,0)),INDEX(Plan!$D$38:$D$51,MATCH(B12&"|"&D12&"|All",Plan!$G$38:$G$51,0))) -> 0 | I12: =IFERROR(INDEX(Plan!$E$38:$E$51,MATCH(B12&"|"&D12&"|"&E12,Plan!$G$38:$G$51,0)),INDEX(Plan!$E$38:$E$51,MATCH(B12&"|"&D12&"|All",Plan!$G$38:$G$51,0))) -> 35 | J12: =IF(F12="","MISSING",IF(AND(F12>=H12,F12<=I12),"OK","OUT")) -> OK | K12: RS
A13: 46293 | B13: Cleaning | C13: 0.4375 | D13: Cleaned chilli moisture | E13: Chilli powder | F13: 10.2 | G13: =IFERROR(INDEX(Plan!$F$38:$F$51,MATCH(B13&"|"&D13&"|"&E13,Plan!$G$38:$G$51,0)),INDEX(Plan!$F$38:$F$51,MATCH(B13&"|"&D13&"|All",Plan!$G$38:$G$51,0))) -> % | H13: =IFERROR(INDEX(Plan!$D$38:$D$51,MATCH(B13&"|"&D13&"|"&E13,Plan!$G$38:$G$51,0)),INDEX(Plan!$D$38:$D$51,MATCH(B13&"|"&D13&"|All",Plan!$G$38:$G$51,0))) -> 8 | I13: =IFERROR(INDEX(Plan!$E$38:$E$51,MATCH(B13&"|"&D13&"|"&E13,Plan!$G$38:$G$51,0)),INDEX(Plan!$E$38:$E$51,MATCH(B13&"|"&D13&"|All",Plan!$G$38:$G$51,0))) -> 11 | J13: =IF(F13="","MISSING",IF(AND(F13>=H13,F13<=I13),"OK","OUT")) -> OK | K13: RS
... A40: 46293 | B40: Cleaning | C40: 0.60416667 | D40: Reject bin since last check | E40: Chilli powder | F40: 28 | G40: =IFERROR(INDEX(Plan!$F$38:$F$51,MATCH(B40&"|"&D40&"|"&E40,Plan!$G$38:$G$51,0)),INDEX(Plan!$F$38:$F$51,MATCH(B40&"|"&D40&"|All",Plan!$G$38:$G$51,0))) -> kg | H40: =IFERROR(INDEX(Plan!$D$38:$D$51,MATCH(B40&"|"&D40&"|"&E40,Plan!$G$38:$G$51,0)),INDEX(Plan!$D$38:$D$51,MATCH(B40&"|"&D40&"|All",Plan!$G$38:$G$51,0))) -> 0 | I40: =IFERROR(INDEX(Plan!$E$38:$E$51,MATCH(B40&"|"&D40&"|"&E40,Plan!$G$38:$G$51,0)),INDEX(Plan!$E$38:$E$51,MATCH(B40&"|"&D40&"|All",Plan!$G$38:$G$51,0))) -> 35 | J40: =IF(F40="","MISSING",IF(AND(F40>=H40,F40<=I40),"OK","OUT")) -> OK | K40: RS
A41: 46293 | B41: Cleaning | C41: 0.60416667 | D41: Cleaned chilli moisture | E41: Chilli powder | G41: =IFERROR(INDEX(Plan!$F$38:$F$51,MATCH(B41&"|"&D41&"|"&E41,Plan!$G$38:$G$51,0)),INDEX(Plan!$F$38:$F$51,MATCH(B41&"|"&D41&"|All",Plan!$G$38:$G$51,0))) -> % | H41: =IFERROR(INDEX(Plan!$D$38:$D$51,MATCH(B41&"|"&D41&"|"&E41,Plan!$G$38:$G$51,0)),INDEX(Plan!$D$38:$D$51,MATCH(B41&"|"&D41&"|All",Plan!$G$38:$G$51,0))) -> 8 | I41: =IFERROR(INDEX(Plan!$E$38:$E$51,MATCH(B41&"|"&D41&"|"&E41,Plan!$G$38:$G$51,0)),INDEX(Plan!$E$38:$E$51,MATCH(B41&"|"&D41&"|All",Plan!$G$38:$G$51,0))) -> 11 | J41: =IF(F41="","MISSING",IF(AND(F41>=H41,F41<=I41),"OK","OUT")) -> MISSING | K41: RS
A42: 46293 | B42: Cleaning | C42: 0.625 | D42: Raw feed rate | E42: Chilli powder | F42: 1090 | G42: =IFERROR(INDEX(Plan!$F$38:$F$51,MATCH(B42&"|"&D42&"|"&E42,Plan!$G$38:$G$51,0)),INDEX(Plan!$F$38:$F$51,MATCH(B42&"|"&D42&"|All",Plan!$G$38:$G$51,0))) -> kg/hr | H42: =IFERROR(INDEX(Plan!$D$38:$D$51,MATCH(B42&"|"&D42&"|"&E42,Plan!$G$38:$G$51,0)),INDEX(Plan!$D$38:$D$51,MATCH(B42&"|"&D42&"|All",Plan!$G$38:$G$51,0))) -> 1050 | I42: =IFERROR(INDEX(Plan!$E$38:$E$51,MATCH(B42&"|"&D42&"|"&E42,Plan!$G$38:$G$51,0)),INDEX(Plan!$E$38:$E$51,MATCH(B42&"|"&D42&"|All",Plan!$G$38:$G$51,0))) -> 1300 | J42: =IF(F42="","MISSING",IF(AND(F42>=H42,F42<=I42),"OK","OUT")) -> OK | K42: RS
A43: 46293 | B43: Cleaning | C43: 0.625 | D43: Foreign matter and stalks in raw sample | E43: Chilli powder | F43: 1.2 | G43: =IFERROR(INDEX(Plan!$F$38:$F$51,MATCH(B43&"|"&D43&"|"&E43,Plan!$G$38:$G$51,0)),INDEX(Plan!$F$38:$F$51,MATCH(B43&"|"&D43&"|All",Plan!$G$38:$G$51,0))) -> % | H43: =IFERROR(INDEX(Plan!$D$38:$D$51,MATCH(B43&"|"&D43&"|"&E43,Plan!$G$38:$G$51,0)),INDEX(Plan!$D$38:$D$51,MATCH(B43&"|"&D43&"|All",Plan!$G$38:$G$51,0))) -> 0 | I43: =IFERROR(INDEX(Plan!$E$38:$E$51,MATCH(B43&"|"&D43&"|"&E43,Plan!$G$38:$G$51,0)),INDEX(Plan!$E$38:$E$51,MATCH(B43&"|"&D43&"|All",Plan!$G$38:$G$51,0))) -> 2 | J43: =IF(F43="","MISSING",IF(AND(F43>=H43,F43<=I43),"OK","OUT")) -> OK | K43: RS
A44: 46293 | B44: Cleaning | C44: 0.625 | D44: Reject bin since last check | E44: Chilli powder | F44: 28 | G44: =IFERROR(INDEX(Plan!$F$38:$F$51,MATCH(B44&"|"&D44&"|"&E44,Plan!$G$38:$G$51,0)),INDEX(Plan!$F$38:$F$51,MATCH(B44&"|"&D44&"|All",Plan!$G$38:$G$51,0))) -> kg | H44: =IFERROR(INDEX(Plan!$D$38:$D$51,MATCH(B44&"|"&D44&"|"&E44,Plan!$G$38:$G$51,0)),INDEX(Plan!$D$38:$D$51,MATCH(B44&"|"&D44&"|All",Plan!$G$38:$G$51,0))) -> 0 | I44: =IFERROR(INDEX(Plan!$E$38:$E$51,MATCH(B44&"|"&D44&"|"&E44,Plan!$G$38:$G$51,0)),INDEX(Plan!$E$38:$E$51,MATCH(B44&"|"&D44&"|All",Plan!$G$38:$G$51,0))) -> 35 | J44: =IF(F44="","MISSING",IF(AND(F44>=H44,F44<=I44),"OK","OUT")) -> OK | K44: RS
A45: 46293 | B45: Cleaning | C45: 0.625 | D45: Cleaned chilli moisture | E45: Chilli powder | F45: 10.4 | G45: =IFERROR(INDEX(Plan!$F$38:$F$51,MATCH(B45&"|"&D45&"|"&E45,Plan!$G$38:$G$51,0)),INDEX(Plan!$F$38:$F$51,MATCH(B45&"|"&D45&"|All",Plan!$G$38:$G$51,0))) -> % | H45: =IFERROR(INDEX(Plan!$D$38:$D$51,MATCH(B45&"|"&D45&"|"&E45,Plan!$G$38:$G$51,0)),INDEX(Plan!$D$38:$D$51,MATCH(B45&"|"&D45&"|All",Plan!$G$38:$G$51,0))) -> 8 | I45: =IFERROR(INDEX(Plan!$E$38:$E$51,MATCH(B45&"|"&D45&"|"&E45,Plan!$G$38:$G$51,0)),INDEX(Plan!$E$38:$E$51,MATCH(B45&"|"&D45&"|All",Plan!$G$38:$G$51,0))) -> 11 | J45: =IF(F45="","MISSING",IF(AND(F45>=H45,F45<=I45),"OK","OUT")) -> OK | K45: RS
A46: 46293 | B46: Cleaning | C46: 0.64583333 | D46: Raw feed rate | E46: Chilli powder | F46: 1090 | G46: =IFERROR(INDEX(Plan!$F$38:$F$51,MATCH(B46&"|"&D46&"|"&E46,Plan!$G$38:$G$51,0)),INDEX(Plan!$F$38:$F$51,MATCH(B46&"|"&D46&"|All",Plan!$G$38:$G$51,0))) -> kg/hr | H46: =IFERROR(INDEX(Plan!$D$38:$D$51,MATCH(B46&"|"&D46&"|"&E46,Plan!$G$38:$G$51,0)),INDEX(Plan!$D$38:$D$51,MATCH(B46&"|"&D46&"|All",Plan!$G$38:$G$51,0))) -> 1050 | I46: =IFERROR(INDEX(Plan!$E$38:$E$51,MATCH(B46&"|"&D46&"|"&E46,Plan!$G$38:$G$51,0)),INDEX(Plan!$E$38:$E$51,MATCH(B46&"|"&D46&"|All",Plan!$G$38:$G$51,0))) -> 1300 | J46: =IF(F46="","MISSING",IF(AND(F46>=H46,F46<=I46),"OK","OUT")) -> OK | K46: RS
A47: 46293 | B47: Cleaning | C47: 0.64583333 | D47: Foreign matter and stalks in raw sample | E47: Chilli powder | F47: 1.2 | G47: =IFERROR(INDEX(Plan!$F$38:$F$51,MATCH(B47&"|"&D47&"|"&E47,Plan!$G$38:$G$51,0)),INDEX(Plan!$F$38:$F$51,MATCH(B47&"|"&D47&"|All",Plan!$G$38:$G$51,0))) -> % | H47: =IFERROR(INDEX(Plan!$D$38:$D$51,MATCH(B47&"|"&D47&"|"&E47,Plan!$G$38:$G$51,0)),INDEX(Plan!$D$38:$D$51,MATCH(B47&"|"&D47&"|All",Plan!$G$38:$G$51,0))) -> 0 | I47: =IFERROR(INDEX(Plan!$E$38:$E$51,MATCH(B47&"|"&D47&"|"&E47,Plan!$G$38:$G$51,0)),INDEX(Plan!$E$38:$E$51,MATCH(B47&"|"&D47&"|All",Plan!$G$38:$G$51,0))) -> 2 | J47: =IF(F47="","MISSING",IF(AND(F47>=H47,F47<=I47),"OK","OUT")) -> OK | K47: RS
A48: 46293 | B48: Cleaning | C48: 0.64583333 | D48: Reject bin since last check | E48: Chilli powder | F48: 27 | G48: =IFERROR(INDEX(Plan!$F$38:$F$51,MATCH(B48&"|"&D48&"|"&E48,Plan!$G$38:$G$51,0)),INDEX(Plan!$F$38:$F$51,MATCH(B48&"|"&D48&"|All",Plan!$G$38:$G$51,0))) -> kg | H48: =IFERROR(INDEX(Plan!$D$38:$D$51,MATCH(B48&"|"&D48&"|"&E48,Plan!$G$38:$G$51,0)),INDEX(Plan!$D$38:$D$51,MATCH(B48&"|"&D48&"|All",Plan!$G$38:$G$51,0))) -> 0 | I48: =IFERROR(INDEX(Plan!$E$38:$E$51,MATCH(B48&"|"&D48&"|"&E48,Plan!$G$38:$G$51,0)),INDEX(Plan!$E$38:$E$51,MATCH(B48&"|"&D48&"|All",Plan!$G$38:$G$51,0))) -> 35 | J48: =IF(F48="","MISSING",IF(AND(F48>=H48,F48<=I48),"OK","OUT")) -> OK | K48: RS
A49: 46293 | B49: Cleaning | C49: 0.64583333 | D49: Cleaned chilli moisture | E49: Chilli powder | F49: 10.5 | G49: =IFERROR(INDEX(Plan!$F$38:$F$51,MATCH(B49&"|"&D49&"|"&E49,Plan!$G$38:$G$51,0)),INDEX(Plan!$F$38:$F$51,MATCH(B49&"|"&D49&"|All",Plan!$G$38:$G$51,0))) -> % | H49: =IFERROR(INDEX(Plan!$D$38:$D$51,MATCH(B49&"|"&D49&"|"&E49,Plan!$G$38:$G$51,0)),INDEX(Plan!$D$38:$D$51,MATCH(B49&"|"&D49&"|All",Plan!$G$38:$G$51,0))) -> 8 | I49: =IFERROR(INDEX(Plan!$E$38:$E$51,MATCH(B49&"|"&D49&"|"&E49,Plan!$G$38:$G$51,0)),INDEX(Plan!$E$38:$E$51,MATCH(B49&"|"&D49&"|All",Plan!$G$38:$G$51,0))) -> 11 | J49: =IF(F49="","MISSING",IF(AND(F49>=H49,F49<=I49),"OK","OUT")) -> OK | K49: RS
A50: 46293 | B50: Cleaning | C50: 0.66666667 | D50: Raw feed rate | E50: Chilli powder | F50: 1090 | G50: =IFERROR(INDEX(Plan!$F$38:$F$51,MATCH(B50&"|"&D50&"|"&E50,Plan!$G$38:$G$51,0)),INDEX(Plan!$F$38:$F$51,MATCH(B50&"|"&D50&"|All",Plan!$G$38:$G$51,0))) -> kg/hr | H50: =IFERROR(INDEX(Plan!$D$38:$D$51,MATCH(B50&"|"&D50&"|"&E50,Plan!$G$38:$G$51,0)),INDEX(Plan!$D$38:$D$51,MATCH(B50&"|"&D50&"|All",Plan!$G$38:$G$51,0))) -> 1050 | I50: =IFERROR(INDEX(Plan!$E$38:$E$51,MATCH(B50&"|"&D50&"|"&E50,Plan!$G$38:$G$51,0)),INDEX(Plan!$E$38:$E$51,MATCH(B50&"|"&D50&"|All",Plan!$G$38:$G$51,0))) -> 1300 | J50: =IF(F50="","MISSING",IF(AND(F50>=H50,F50<=I50),"OK","OUT")) -> OK | K50: RS
A51: 46293 | B51: Cleaning | C51: 0.66666667 | D51: Foreign matter and stalks in raw sample | E51: Chilli powder | F51: 1.1 | G51: =IFERROR(INDEX(Plan!$F$38:$F$51,MATCH(B51&"|"&D51&"|"&E51,Plan!$G$38:$G$51,0)),INDEX(Plan!$F$38:$F$51,MATCH(B51&"|"&D51&"|All",Plan!$G$38:$G$51,0))) -> % | H51: =IFERROR(INDEX(Plan!$D$38:$D$51,MATCH(B51&"|"&D51&"|"&E51,Plan!$G$38:$G$51,0)),INDEX(Plan!$D$38:$D$51,MATCH(B51&"|"&D51&"|All",Plan!$G$38:$G$51,0))) -> 0 | I51: =IFERROR(INDEX(Plan!$E$38:$E$51,MATCH(B51&"|"&D51&"|"&E51,Plan!$G$38:$G$51,0)),INDEX(Plan!$E$38:$E$51,MATCH(B51&"|"&D51&"|All",Plan!$G$38:$G$51,0))) -> 2 | J51: =IF(F51="","MISSING",IF(AND(F51>=H51,F51<=I51),"OK","OUT")) -> OK | K51: RS
A52: 46293 | B52: Cleaning | C52: 0.66666667 | D52: Reject bin since last check | E52: Chilli powder | F52: 28 | G52: =IFERROR(INDEX(Plan!$F$38:$F$51,MATCH(B52&"|"&D52&"|"&E52,Plan!$G$38:$G$51,0)),INDEX(Plan!$F$38:$F$51,MATCH(B52&"|"&D52&"|All",Plan!$G$38:$G$51,0))) -> kg | H52: =IFERROR(INDEX(Plan!$D$38:$D$51,MATCH(B52&"|"&D52&"|"&E52,Plan!$G$38:$G$51,0)),INDEX(Plan!$D$38:$D$51,MATCH(B52&"|"&D52&"|All",Plan!$G$38:$G$51,0))) -> 0 | I52: =IFERROR(INDEX(Plan!$E$38:$E$51,MATCH(B52&"|"&D52&"|"&E52,Plan!$G$38:$G$51,0)),INDEX(Plan!$E$38:$E$51,MATCH(B52&"|"&D52&"|All",Plan!$G$38:$G$51,0))) -> 35 | J52: =IF(F52="","MISSING",IF(AND(F52>=H52,F52<=I52),"OK","OUT")) -> OK | K52: RS
A53: 46293 | B53: Cleaning | C53: 0.66666667 | D53: Cleaned chilli moisture | E53: Chilli powder | F53: 10.1 | G53: =IFERROR(INDEX(Plan!$F$38:$F$51,MATCH(B53&"|"&D53&"|"&E53,Plan!$G$38:$G$51,0)),INDEX(Plan!$F$38:$F$51,MATCH(B53&"|"&D53&"|All",Plan!$G$38:$G$51,0))) -> % | H53: =IFERROR(INDEX(Plan!$D$38:$D$51,MATCH(B53&"|"&D53&"|"&E53,Plan!$G$38:$G$51,0)),INDEX(Plan!$D$38:$D$51,MATCH(B53&"|"&D53&"|All",Plan!$G$38:$G$51,0))) -> 8 | I53: =IFERROR(INDEX(Plan!$E$38:$E$51,MATCH(B53&"|"&D53&"|"&E53,Plan!$G$38:$G$51,0)),INDEX(Plan!$E$38:$E$51,MATCH(B53&"|"&D53&"|All",Plan!$G$38:$G$51,0))) -> 11 | J53: =IF(F53="","MISSING",IF(AND(F53>=H53,F53<=I53),"OK","OUT")) -> OK | K53: RS
... A170: 46297 | B170: Packing | C170: 0.52083333 | D170: Filler speed | E170: Chilli powder | F170: 34 | G170: =IFERROR(INDEX(Plan!$F$38:$F$51,MATCH(B170&"|"&D170&"|"&E170,Plan!$G$38:$G$51,0)),INDEX(Plan!$F$38:$F$51,MATCH(B170&"|"&D170&"|All",Plan!$G$38:$G$51,0))) -> pouches/min | H170: =IFERROR(INDEX(Plan!$D$38:$D$51,MATCH(B170&"|"&D170&"|"&E170,Plan!$G$38:$G$51,0)),INDEX(Plan!$D$38:$D$51,MATCH(B170&"|"&D170&"|All",Plan!$G$38:$G$51,0))) -> 38 | I170: =IFERROR(INDEX(Plan!$E$38:$E$51,MATCH(B170&"|"&D170&"|"&E170,Plan!$G$38:$G$51,0)),INDEX(Plan!$E$38:$E$51,MATCH(B170&"|"&D170&"|All",Plan!$G$38:$G$51,0))) -> 42 | J170: =IF(F170="","MISSING",IF(AND(F170>=H170,F170<=I170),"OK","OUT")) -> OUT | K170: PD
A171: 46297 | B171: Packing | C171: 0.52083333 | D171: Avg pouch weight (10 pouches) | E171: Chilli powder | G171: =IFERROR(INDEX(Plan!$F$38:$F$51,MATCH(B171&"|"&D171&"|"&E171,Plan!$G$38:$G$51,0)),INDEX(Plan!$F$38:$F$51,MATCH(B171&"|"&D171&"|All",Plan!$G$38:$G$51,0))) -> g | H171: =IFERROR(INDEX(Plan!$D$38:$D$51,MATCH(B171&"|"&D171&"|"&E171,Plan!$G$38:$G$51,0)),INDEX(Plan!$D$38:$D$51,MATCH(B171&"|"&D171&"|All",Plan!$G$38:$G$51,0))) -> 200 | I171: =IFERROR(INDEX(Plan!$E$38:$E$51,MATCH(B171&"|"&D171&"|"&E171,Plan!$G$38:$G$51,0)),INDEX(Plan!$E$38:$E$51,MATCH(B171&"|"&D171&"|All",Plan!$G$38:$G$51,0))) -> 203 | J171: =IF(F171="","MISSING",IF(AND(F171>=H171,F171<=I171),"OK","OUT")) -> MISSING | K171: PD
A172: 46297 | B172: Packing | C172: 0.54166667 | D172: Dust extraction suction at filler | E172: Chilli powder | F172: 134 | G172: =IFERROR(INDEX(Plan!$F$38:$F$51,MATCH(B172&"|"&D172&"|"&E172,Plan!$G$38:$G$51,0)),INDEX(Plan!$F$38:$F$51,MATCH(B172&"|"&D172&"|All",Plan!$G$38:$G$51,0))) -> Pa | H172: =IFERROR(INDEX(Plan!$D$38:$D$51,MATCH(B172&"|"&D172&"|"&E172,Plan!$G$38:$G$51,0)),INDEX(Plan!$D$38:$D$51,MATCH(B172&"|"&D172&"|All",Plan!$G$38:$G$51,0))) -> 250 | I172: =IFERROR(INDEX(Plan!$E$38:$E$51,MATCH(B172&"|"&D172&"|"&E172,Plan!$G$38:$G$51,0)),INDEX(Plan!$E$38:$E$51,MATCH(B172&"|"&D172&"|All",Plan!$G$38:$G$51,0))) -> 400 | J172: =IF(F172="","MISSING",IF(AND(F172>=H172,F172<=I172),"OK","OUT")) -> OUT | K172: PD
A173: 46297 | B173: Packing | C173: 0.54166667 | D173: Seal jaw temp | E173: Chilli powder | F173: 175 | G173: =IFERROR(INDEX(Plan!$F$38:$F$51,MATCH(B173&"|"&D173&"|"&E173,Plan!$G$38:$G$51,0)),INDEX(Plan!$F$38:$F$51,MATCH(B173&"|"&D173&"|All",Plan!$G$38:$G$51,0))) -> °C | H173: =IFERROR(INDEX(Plan!$D$38:$D$51,MATCH(B173&"|"&D173&"|"&E173,Plan!$G$38:$G$51,0)),INDEX(Plan!$D$38:$D$51,MATCH(B173&"|"&D173&"|All",Plan!$G$38:$G$51,0))) -> 150 | I173: =IFERROR(INDEX(Plan!$E$38:$E$51,MATCH(B173&"|"&D173&"|"&E173,Plan!$G$38:$G$51,0)),INDEX(Plan!$E$38:$E$51,MATCH(B173&"|"&D173&"|All",Plan!$G$38:$G$51,0))) -> 165 | J173: =IF(F173="","MISSING",IF(AND(F173>=H173,F173<=I173),"OK","OUT")) -> OUT | K173: PD
A174: 46297 | B174: Packing | C174: 0.54166667 | D174: Filler speed | E174: Chilli powder | F174: 34 | G174: =IFERROR(INDEX(Plan!$F$38:$F$51,MATCH(B174&"|"&D174&"|"&E174,Plan!$G$38:$G$51,0)),INDEX(Plan!$F$38:$F$51,MATCH(B174&"|"&D174&"|All",Plan!$G$38:$G$51,0))) -> pouches/min | H174: =IFERROR(INDEX(Plan!$D$38:$D$51,MATCH(B174&"|"&D174&"|"&E174,Plan!$G$38:$G$51,0)),INDEX(Plan!$D$38:$D$51,MATCH(B174&"|"&D174&"|All",Plan!$G$38:$G$51,0))) -> 38 | I174: =IFERROR(INDEX(Plan!$E$38:$E$51,MATCH(B174&"|"&D174&"|"&E174,Plan!$G$38:$G$51,0)),INDEX(Plan!$E$38:$E$51,MATCH(B174&"|"&D174&"|All",Plan!$G$38:$G$51,0))) -> 42 | J174: =IF(F174="","MISSING",IF(AND(F174>=H174,F174<=I174),"OK","OUT")) -> OUT | K174: PD
A175: 46297 | B175: Packing | C175: 0.54166667 | D175: Avg pouch weight (10 pouches) | E175: Chilli powder | F175: 201.8 | G175: =IFERROR(INDEX(Plan!$F$38:$F$51,MATCH(B175&"|"&D175&"|"&E175,Plan!$G$38:$G$51,0)),INDEX(Plan!$F$38:$F$51,MATCH(B175&"|"&D175&"|All",Plan!$G$38:$G$51,0))) -> g | H175: =IFERROR(INDEX(Plan!$D$38:$D$51,MATCH(B175&"|"&D175&"|"&E175,Plan!$G$38:$G$51,0)),INDEX(Plan!$D$38:$D$51,MATCH(B175&"|"&D175&"|All",Plan!$G$38:$G$51,0))) -> 200 | I175: =IFERROR(INDEX(Plan!$E$38:$E$51,MATCH(B175&"|"&D175&"|"&E175,Plan!$G$38:$G$51,0)),INDEX(Plan!$E$38:$E$51,MATCH(B175&"|"&D175&"|All",Plan!$G$38:$G$51,0))) -> 203 | J175: =IF(F175="","MISSING",IF(AND(F175>=H175,F175<=I175),"OK","OUT")) -> OK | K175: PD
A176: 46297 | B176: Packing | C176: 0.58333333 | D176: Dust extraction suction at filler | E176: Chilli powder | F176: 136 | G176: =IFERROR(INDEX(Plan!$F$38:$F$51,MATCH(B176&"|"&D176&"|"&E176,Plan!$G$38:$G$51,0)),INDEX(Plan!$F$38:$F$51,MATCH(B176&"|"&D176&"|All",Plan!$G$38:$G$51,0))) -> Pa | H176: =IFERROR(INDEX(Plan!$D$38:$D$51,MATCH(B176&"|"&D176&"|"&E176,Plan!$G$38:$G$51,0)),INDEX(Plan!$D$38:$D$51,MATCH(B176&"|"&D176&"|All",Plan!$G$38:$G$51,0))) -> 250 | I176: =IFERROR(INDEX(Plan!$E$38:$E$51,MATCH(B176&"|"&D176&"|"&E176,Plan!$G$38:$G$51,0)),INDEX(Plan!$E$38:$E$51,MATCH(B176&"|"&D176&"|All",Plan!$G$38:$G$51,0))) -> 400 | J176: =IF(F176="","MISSING",IF(AND(F176>=H176,F176<=I176),"OK","OUT")) -> OUT | K176: PD
A177: 46297 | B177: Packing | C177: 0.58333333 | D177: Seal jaw temp | E177: Chilli powder | F177: 175 | G177: =IFERROR(INDEX(Plan!$F$38:$F$51,MATCH(B177&"|"&D177&"|"&E177,Plan!$G$38:$G$51,0)),INDEX(Plan!$F$38:$F$51,MATCH(B177&"|"&D177&"|All",Plan!$G$38:$G$51,0))) -> °C | H177: =IFERROR(INDEX(Plan!$D$38:$D$51,MATCH(B177&"|"&D177&"|"&E177,Plan!$G$38:$G$51,0)),INDEX(Plan!$D$38:$D$51,MATCH(B177&"|"&D177&"|All",Plan!$G$38:$G$51,0))) -> 150 | I177: =IFERROR(INDEX(Plan!$E$38:$E$51,MATCH(B177&"|"&D177&"|"&E177,Plan!$G$38:$G$51,0)),INDEX(Plan!$E$38:$E$51,MATCH(B177&"|"&D177&"|All",Plan!$G$38:$G$51,0))) -> 165 | J177: =IF(F177="","MISSING",IF(AND(F177>=H177,F177<=I177),"OK","OUT")) -> OUT | K177: PD
A178: 46297 | B178: Packing | C178: 0.58333333 | D178: Filler speed | E178: Chilli powder | F178: 34 | G178: =IFERROR(INDEX(Plan!$F$38:$F$51,MATCH(B178&"|"&D178&"|"&E178,Plan!$G$38:$G$51,0)),INDEX(Plan!$F$38:$F$51,MATCH(B178&"|"&D178&"|All",Plan!$G$38:$G$51,0))) -> pouches/min | H178: =IFERROR(INDEX(Plan!$D$38:$D$51,MATCH(B178&"|"&D178&"|"&E178,Plan!$G$38:$G$51,0)),INDEX(Plan!$D$38:$D$51,MATCH(B178&"|"&D178&"|All",Plan!$G$38:$G$51,0))) -> 38 | I178: =IFERROR(INDEX(Plan!$E$38:$E$51,MATCH(B178&"|"&D178&"|"&E178,Plan!$G$38:$G$51,0)),INDEX(Plan!$E$38:$E$51,MATCH(B178&"|"&D178&"|All",Plan!$G$38:$G$51,0))) -> 42 | J178: =IF(F178="","MISSING",IF(AND(F178>=H178,F178<=I178),"OK","OUT")) -> OUT | K178: PD
A179: 46297 | B179: Packing | C179: 0.58333333 | D179: Avg pouch weight (10 pouches) | E179: Chilli powder | F179: 201.6 | G179: =IFERROR(INDEX(Plan!$F$38:$F$51,MATCH(B179&"|"&D179&"|"&E179,Plan!$G$38:$G$51,0)),INDEX(Plan!$F$38:$F$51,MATCH(B179&"|"&D179&"|All",Plan!$G$38:$G$51,0))) -> g | H179: =IFERROR(INDEX(Plan!$D$38:$D$51,MATCH(B179&"|"&D179&"|"&E179,Plan!$G$38:$G$51,0)),INDEX(Plan!$D$38:$D$51,MATCH(B179&"|"&D179&"|All",Plan!$G$38:$G$51,0))) -> 200 | I179: =IFERROR(INDEX(Plan!$E$38:$E$51,MATCH(B179&"|"&D179&"|"&E179,Plan!$G$38:$G$51,0)),INDEX(Plan!$E$38:$E$51,MATCH(B179&"|"&D179&"|All",Plan!$G$38:$G$51,0))) -> 203 | J179: =IF(F179="","MISSING",IF(AND(F179>=H179,F179<=I179),"OK","OUT")) -> OK | K179: PD
A180: 46297 | B180: Packing | C180: 0.60416667 | D180: Dust extraction suction at filler | E180: Chilli powder | F180: 136 | G180: =IFERROR(INDEX(Plan!$F$38:$F$51,MATCH(B180&"|"&D180&"|"&E180,Plan!$G$38:$G$51,0)),INDEX(Plan!$F$38:$F$51,MATCH(B180&"|"&D180&"|All",Plan!$G$38:$G$51,0))) -> Pa | H180: =IFERROR(INDEX(Plan!$D$38:$D$51,MATCH(B180&"|"&D180&"|"&E180,Plan!$G$38:$G$51,0)),INDEX(Plan!$D$38:$D$51,MATCH(B180&"|"&D180&"|All",Plan!$G$38:$G$51,0))) -> 250 | I180: =IFERROR(INDEX(Plan!$E$38:$E$51,MATCH(B180&"|"&D180&"|"&E180,Plan!$G$38:$G$51,0)),INDEX(Plan!$E$38:$E$51,MATCH(B180&"|"&D180&"|All",Plan!$G$38:$G$51,0))) -> 400 | J180: =IF(F180="","MISSING",IF(AND(F180>=H180,F180<=I180),"OK","OUT")) -> OUT | K180: PD
A181: 46297 | B181: Packing | C181: 0.60416667 | D181: Seal jaw temp | E181: Chilli powder | F181: 175 | G181: =IFERROR(INDEX(Plan!$F$38:$F$51,MATCH(B181&"|"&D181&"|"&E181,Plan!$G$38:$G$51,0)),INDEX(Plan!$F$38:$F$51,MATCH(B181&"|"&D181&"|All",Plan!$G$38:$G$51,0))) -> °C | H181: =IFERROR(INDEX(Plan!$D$38:$D$51,MATCH(B181&"|"&D181&"|"&E181,Plan!$G$38:$G$51,0)),INDEX(Plan!$D$38:$D$51,MATCH(B181&"|"&D181&"|All",Plan!$G$38:$G$51,0))) -> 150 | I181: =IFERROR(INDEX(Plan!$E$38:$E$51,MATCH(B181&"|"&D181&"|"&E181,Plan!$G$38:$G$51,0)),INDEX(Plan!$E$38:$E$51,MATCH(B181&"|"&D181&"|All",Plan!$G$38:$G$51,0))) -> 165 | J181: =IF(F181="","MISSING",IF(AND(F181>=H181,F181<=I181),"OK","OUT")) -> OUT | K181: PD
A182: 46297 | B182: Packing | C182: 0.60416667 | D182: Filler speed | E182: Chilli powder | F182: 34 | G182: =IFERROR(INDEX(Plan!$F$38:$F$51,MATCH(B182&"|"&D182&"|"&E182,Plan!$G$38:$G$51,0)),INDEX(Plan!$F$38:$F$51,MATCH(B182&"|"&D182&"|All",Plan!$G$38:$G$51,0))) -> pouches/min | H182: =IFERROR(INDEX(Plan!$D$38:$D$51,MATCH(B182&"|"&D182&"|"&E182,Plan!$G$38:$G$51,0)),INDEX(Plan!$D$38:$D$51,MATCH(B182&"|"&D182&"|All",Plan!$G$38:$G$51,0))) -> 38 | I182: =IFERROR(INDEX(Plan!$E$38:$E$51,MATCH(B182&"|"&D182&"|"&E182,Plan!$G$38:$G$51,0)),INDEX(Plan!$E$38:$E$51,MATCH(B182&"|"&D182&"|All",Plan!$G$38:$G$51,0))) -> 42 | J182: =IF(F182="","MISSING",IF(AND(F182>=H182,F182<=I182),"OK","OUT")) -> OUT | K182: PD
...

Sheet 4_Changes
A1: Date | B1: Stage | C1: Time | D1: Change Type | E1: What Changed | F1: From | G1: To | H1: Changed By | I1: Standard Checked (spec, setup sheet or PM plan) | J1: Note
A2: 46293 | B2: Cleaning | C2: 0.44444444 | D2: Material lot | E2: Raw chilli lot | F2: RC-112 (Guntur Teja, graded) | G2: RC-118 (new supplier, ungraded) | H2: Stores | I2: N | J2: Receiving sample not tested for foreign matter
A3: 46293 | B3: Cleaning | C3: 0.48611111 | D3: Machine setting | E3: Raw feed rate | F3: 1,090 kg/hr | G3: 950 kg/hr | H3: Operator RS | I3: N | J3: Slowed to stop reject bin overflowing
A4: 46293 | B4: Cleaning | C4: 0.5625 | D4: Material lot | E4: Raw chilli lot | F4: RC-118 | G4: RC-112 | H4: Shift lead | I4: Y | J4: RC-118 sent back to stores for re-sorting
A5: 46293 | B5: Cleaning | C5: 0.5625 | D5: Machine setting | E5: Raw feed rate | F5: 950 kg/hr | G5: 1,090 kg/hr | H5: Shift lead | I5: Y
A6: 46295 | B6: Grinding | C6: 0.375 | D6: Maintenance deferred | E6: Hammer set replacement (PM) | F6: Due at 400 hours | G6: Deferred to Saturday | H6: Maintenance planner | I6: N | J6: Hammer set at 412 hours at shift start
A7: 46295 | B7: Grinding | C7: 0.46875 | D7: Machine setting | E7: Mill feed rate | F7: 1,030 kg/hr | G7: 1,200 kg/hr | H7: Operator MK | I7: N | J7: Raised to catch up on output
A8: 46295 | B8: Grinding | C8: 0.5625 | D8: Machine setting | E8: Mill feed rate | F8: 1,200 kg/hr | G8: 1,030 kg/hr | H8: QA | I8: Y | J8: QA held 12:00 to 1:00 powder for low colour
A9: 46295 | B9: Grinding | C9: 0.625 | D9: Maintenance repair | E9: Hammer set | F9: 412 hours, worn | G9: New set | H9: Maintenance | I9: Y | J9: Run hours reset to 0
A10: 46297 | B10: Packing | C10: 0.375 | D10: Maintenance repair | E10: Compressor service | F10: Due | G10: Serviced | H10: Maintenance | I10: NA | J10: Pulse jet air line to dust collector isolated during service
A11: 46297 | B11: Packing | C11: 0.48611111 | D11: Machine setting | E11: Seal jaw temp | F11: 158 °C | G11: 175 °C | H11: Operator PD | I11: N | J11: Raised to stop leakers
A12: 46297 | B12: Packing | C12: 0.50694444 | D12: Machine setting | E12: Filler speed | F12: 40 | G12: 34 | H12: Operator PD | I12: N | J12: Slowed to reduce jams
A13: 46297 | B13: Packing | C13: 0.61111111 | D13: Maintenance repair | E13: Dust collector pulse jet air valve | F13: Closed | G13: Open, bags pulsed | H13: Maintenance | I13: Y | J13: Found valve still closed after compressor service
A14: 46297 | B14: Packing | C14: 0.625 | D14: Machine setting | E14: Seal jaw temp and filler speed | F14: 175 °C, 34 | G14: 158 °C, 40 | H14: Shift lead | I14: Y | J14: Back to setup sheet

Sheet 5_Response
A1: Date | B1: Stage | C1: Problem Seen | D1: Noticed At | E1: Escalated To | F1: Escalated At | G1: Action Taken | H1: Fixed At | I1: Worked? | J1: Minutes Noticed to Fixed | K1: Recorded By
A2: 46293 | B2: Cleaning | C2: Reject bin overflowing | D2: 0.46527778 | G2: Emptied bin, slowed feed to 950 kg/hr | I2: Partly | J2: =IF(H2="","",ROUND((H2-D2)*1440,0)) | K2: RS
A3: 46293 | B3: Cleaning | C3: Reject bin overflowing | D3: 0.46527778 | E3: Shift lead | F3: 0.52777778 | G3: Switched back to graded lot RC-112, RC-118 sent for re-sorting | H3: 0.5625 | I3: Yes | J3: =IF(H3="","",ROUND((H3-D3)*1440,0)) -> 140 | K3: RS
A4: 46295 | B4: Grinding | C4: Output low, powder coarse | D4: 0.45833333 | G4: Raised mill feed to 1,200 kg/hr | I4: No | J4: =IF(H4="","",ROUND((H4-D4)*1440,0)) | K4: MK
A5: 46295 | B5: Grinding | C5: Colour ASTA low (found by QA) | D5: 0.50347222 | E5: Maintenance | F5: 0.51388889 | G5: QA held powder, feed back to 1,030; hammer set replaced | H5: 0.625 | I5: Yes | J5: =IF(H5="","",ROUND((H5-D5)*1440,0)) -> 175 | K5: MK
A6: 46297 | B6: Packing | C6: Leaking pouches, jaws jamming | D6: 0.47916667 | G6: Raised seal temp to 175 °C, slowed to 34 per min | I6: No | J6: =IF(H6="","",ROUND((H6-D6)*1440,0)) | K6: PD
A7: 46297 | B7: Packing | C7: Leaking pouches, jaws jamming | D7: 0.47916667 | E7: Maintenance | F7: 0.57291667 | G7: Opened pulse jet valve on dust collector, cleaned jaws | H7: 0.625 | I7: Yes | J7: =IF(H7="","",ROUND((H7-D7)*1440,0)) -> 210 | K7: PD

Sheet Shift_Summary
A1: Shift Summary (calculated)
A3: Stage | B3: Date | C3: Target | D3: Actual Good | E3: % of Target | F3: Rejects | G3: Stop Minutes | H3: Out of Spec Readings | I3: Missing Readings | J3: Changes Logged | K3: Changes Without Standard Check | L3: Actions That Did Not Fix It | M3: Avg Min Noticed to Fixed
A4: Cleaning | B4: 46293 | C4: =SUMIFS(1_Output!$H:$H,1_Output!$B:$B,A4,1_Output!$A:$A,B4) -> 7130.5842 | D4: =SUMIFS(1_Output!$E:$E,1_Output!$B:$B,A4,1_Output!$A:$A,B4) -> 6487 | E4: =IF(C4=0,"",D4/C4) -> 0.90974313 | F4: =SUMIFS(1_Output!$F:$F,1_Output!$B:$B,A4,1_Output!$A:$A,B4) -> 489 | G4: =SUMIFS(2_Stops!$E:$E,2_Stops!$B:$B,A4,2_Stops!$A:$A,B4) -> 26 | H4: =COUNTIFS(3_Settings!$B:$B,A4,3_Settings!$A:$A,B4,3_Settings!$J:$J,"OUT") -> 13 | I4: =COUNTIFS(3_Settings!$B:$B,A4,3_Settings!$A:$A,B4,3_Settings!$J:$J,"MISSING") -> 1 | J4: =COUNTIFS(4_Changes!$B:$B,A4,4_Changes!$A:$A,B4) -> 4 | K4: =COUNTIFS(4_Changes!$B:$B,A4,4_Changes!$A:$A,B4,4_Changes!$I:$I,"N") -> 2 | L4: =COUNTIFS(5_Response!$B:$B,A4,5_Response!$A:$A,B4,5_Response!$I:$I,"No")+COUNTIFS(5_Response!$B:$B,A4,5_Response!$A:$A,B4,5_Response!$I:$I,"Partly") -> 1 | M4: =IFERROR(AVERAGEIFS(5_Response!$J:$J,5_Response!$B:$B,A4,5_Response!$A:$A,B4),"") -> 140
A5: Grinding | B5: 46295 | C5: =SUMIFS(1_Output!$H:$H,1_Output!$B:$B,A5,1_Output!$A:$A,B5) -> 6916.6667 | D5: =SUMIFS(1_Output!$E:$E,1_Output!$B:$B,A5,1_Output!$A:$A,B5) -> 4963 | E5: =IF(C5=0,"",D5/C5) -> 0.71754217 | F5: =SUMIFS(1_Output!$F:$F,1_Output!$B:$B,A5,1_Output!$A:$A,B5) -> 1041 | G5: =SUMIFS(2_Stops!$E:$E,2_Stops!$B:$B,A5,2_Stops!$A:$A,B5) -> 52 | H5: =COUNTIFS(3_Settings!$B:$B,A5,3_Settings!$A:$A,B5,3_Settings!$J:$J,"OUT") -> 32 | I5: =COUNTIFS(3_Settings!$B:$B,A5,3_Settings!$A:$A,B5,3_Settings!$J:$J,"MISSING") -> 0 | J5: =COUNTIFS(4_Changes!$B:$B,A5,4_Changes!$A:$A,B5) -> 4 | K5: =COUNTIFS(4_Changes!$B:$B,A5,4_Changes!$A:$A,B5,4_Changes!$I:$I,"N") -> 2 | L5: =COUNTIFS(5_Response!$B:$B,A5,5_Response!$A:$A,B5,5_Response!$I:$I,"No")+COUNTIFS(5_Response!$B:$B,A5,5_Response!$A:$A,B5,5_Response!$I:$I,"Partly") -> 1 | M5: =IFERROR(AVERAGEIFS(5_Response!$J:$J,5_Response!$B:$B,A5,5_Response!$A:$A,B5),"") -> 175
A6: Packing | B6: 46297 | C6: =SUMIFS(1_Output!$H:$H,1_Output!$B:$B,A6,1_Output!$A:$A,B6) -> 32536 | D6: =SUMIFS(1_Output!$E:$E,1_Output!$B:$B,A6,1_Output!$A:$A,B6) -> 27664 | E6: =IF(C6=0,"",D6/C6) -> 0.85025818 | F6: =SUMIFS(1_Output!$F:$F,1_Output!$B:$B,A6,1_Output!$A:$A,B6) -> 912 | G6: =SUMIFS(2_Stops!$E:$E,2_Stops!$B:$B,A6,2_Stops!$A:$A,B6) -> 53 | H6: =COUNTIFS(3_Settings!$B:$B,A6,3_Settings!$A:$A,B6,3_Settings!$J:$J,"OUT") -> 18 | I6: =COUNTIFS(3_Settings!$B:$B,A6,3_Settings!$A:$A,B6,3_Settings!$J:$J,"MISSING") -> 1 | J6: =COUNTIFS(4_Changes!$B:$B,A6,4_Changes!$A:$A,B6) -> 5 | K6: =COUNTIFS(4_Changes!$B:$B,A6,4_Changes!$A:$A,B6,4_Changes!$I:$I,"N") -> 2 | L6: =COUNTIFS(5_Response!$B:$B,A6,5_Response!$A:$A,B6,5_Response!$I:$I,"No")+COUNTIFS(5_Response!$B:$B,A6,5_Response!$A:$A,B6,5_Response!$I:$I,"Partly") -> 1 | M6: =IFERROR(AVERAGEIFS(5_Response!$J:$J,5_Response!$B:$B,A6,5_Response!$A:$A,B6),"") -> 210
A8: Grinding rejects include powder held by QA for low colour. Slow running shows as OUT on Raw feed rate and Filler speed.

Sheet Answer_Key
A1: Answer Key: expected findings (do NOT feed to the LLM)
A3: Stage | B3: Date | C3: Root cause | D3: First signal in the data | E3: Clue in 4_Changes | F3: Expected floor actions | G3: Escalate to
A4: Cleaning | B4: 46293 | C4: New raw chilli lot RC-118 from an ungraded supplier carries 6 to 7% stalks and foreign matter (spec 2% max). Cleaning yield falls from 95% to about 87%, the reject bin overflows twice, and the operator slows the feed to 950 kg/hr, so grinding is starved. | D4: 3_Settings at 11:00: foreign matter 4.0% OUT and reject bin 44 kg OUT, 20 min after the lot change. | E4: Raw lot RC-112 to RC-118 at 10:40 with Standard Checked = N (receiving sample not tested). | F4: Sample the raw lot at once; if foreign matter is above 2%, stop feeding it and switch back to the graded lot; send the bad lot for pre-sorting; add a second reject bin while running it; test receiving samples before issue. | G4: Shift lead, QA, stores
A5: Grinding | B5: 46295 | C5: Hammer set run past its 400 hour life (PM deferred). Worn hammers grind coarse: 40 mesh pass falls from 97% to below 90%, so output drops. The operator raises feed to 1,200 kg/hr to catch up, which overloads the mill and heats the powder to 46 to 49 °C. Colour falls to about 114 ASTA and QA holds an hour of powder. | D5: 3_Settings: hammer hours 412 OUT from the first check at 9:30; sieve pass 94.5% OUT at 10:30, before the feed change. | E5: PM hammer replacement deferred at 9:00 with Standard Checked = N; feed raised to 1,200 at 11:15 (N). | F5: Do not raise feed to catch up on a worn mill; keep powder below 42 °C; call maintenance when pass drops below 95% with hammers past 400 h; ask QA to test colour before continuing; never defer a hammer PM without a plan. | G5: Maintenance, QA
A6: Packing | B6: 46297 | C6: Pulse jet air to the dust collector was left isolated after a compressor service. Filter bags blind, suction at the fillers falls from 320 to about 140 Pa, spice dust settles on the film at the seal jaws, and leakers and jams rise. Raising seal temp to 175 °C and slowing to 34 per min treat the symptom and burn seals. | D6: 3_Settings: dust extraction suction falling from 9:30 and OUT at 11:00; leakers start at the 11:30 check, 30 min later. | E6: Compressor service at 9:00 (pulse jet air isolated), then seal temp raised to 175 °C at 11:40 (N) and speed cut to 34 at 12:10 (N). | F6: Check suction at the filler every 30 min; if below 250 Pa call maintenance and check the dust collector, not the seal jaws; keep seal temp on the setup sheet; after any compressor work confirm all air lines are open. | G6: Maintenance, QA

Sheet Lists
A1: Stage | B1: Stop type | C1: 4M | D1: Change type | E1: Y/N | F1: Worked
A2: Cleaning | B2: Breakdown | C2: Man | D2: Material lot | E2: Y | F2: Yes
A3: Grinding | B3: Minor stop | C3: Machine | D3: Machine setting | E3: N | F3: Partly
A4: Packing | B4: Changeover | C4: Method | D4: Person on station | E4: NA | F4: No
B5: Process delay | C5: Material | D5: Maintenance repair
B6: Quality hold | D6: Maintenance deferred
B7: Waiting (starved)
B8: Waiting (blocked)
B9: Line blocked (buffer full)
B10: Supply out
B11: Cleaning
